2025-10-12T19:31:37: INFO:firestore_service:Firestore service initialized for project: image-genie-ff577
2025-10-12T19:31:37: INFO:in_memory_store:In-memory token store initialized
2025-10-12T19:33:30: Traceback (most recent call last):
2025-10-12T19:33:30:   File "C:\USERS\SAHAN\APPDATA\LOCAL\PROGRAMS\PYTHON\PYTHON313\Lib\site-packages\urllib3\connection.py", line 198, in _new_conn
2025-10-12T19:33:30:     sock = connection.create_connection(
2025-10-12T19:33:30:         (self._dns_host, self.port),
2025-10-12T19:33:30:     ...<2 lines>...
2025-10-12T19:33:30:         socket_options=self.socket_options,
2025-10-12T19:33:30:     )
2025-10-12T19:33:30:   File "C:\USERS\SAHAN\APPDATA\LOCAL\PROGRAMS\PYTHON\PYTHON313\Lib\site-packages\urllib3\util\connection.py", line 85, in create_connection
2025-10-12T19:33:30:     raise err
2025-10-12T19:33:30:   File "C:\USERS\SAHAN\APPDATA\LOCAL\PROGRAMS\PYTHON\PYTHON313\Lib\site-packages\urllib3\util\connection.py", line 73, in create_connection
2025-10-12T19:33:30:     sock.connect(sa)
2025-10-12T19:33:30:     ~~~~~~~~~~~~^^^^
2025-10-12T19:33:30: ConnectionRefusedError: [WinError 10061] No connection could be made because the target machine actively refused it
2025-10-12T19:33:30: 
2025-10-12T19:33:30: The above exception was the direct cause of the following exception:
2025-10-12T19:33:30: 
2025-10-12T19:33:30: Traceback (most recent call last):
2025-10-12T19:33:30:   File "C:\USERS\SAHAN\APPDATA\LOCAL\PROGRAMS\PYTHON\PYTHON313\Lib\site-packages\urllib3\connectionpool.py", line 787, in urlopen
2025-10-12T19:33:30:     response = self._make_request(
2025-10-12T19:33:30:         conn,
2025-10-12T19:33:30:     ...<10 lines>...
2025-10-12T19:33:30:         **response_kw,
2025-10-12T19:33:30:     )
2025-10-12T19:33:30:   File "C:\USERS\SAHAN\APPDATA\LOCAL\PROGRAMS\PYTHON\PYTHON313\Lib\site-packages\urllib3\connectionpool.py", line 493, in _make_request
2025-10-12T19:33:30:     conn.request(
2025-10-12T19:33:30:     ~~~~~~~~~~~~^
2025-10-12T19:33:30:         method,
2025-10-12T19:33:30:         ^^^^^^^
2025-10-12T19:33:30:     ...<6 lines>...
2025-10-12T19:33:30:         enforce_content_length=enforce_content_length,
2025-10-12T19:33:30:         ^^^^^^^^^^^^^^^^^^^^^^^^^^^^^^^^^^^^^^^^^^^^^^
2025-10-12T19:33:30:     )
2025-10-12T19:33:30:     ^
2025-10-12T19:33:30:   File "C:\USERS\SAHAN\APPDATA\LOCAL\PROGRAMS\PYTHON\PYTHON313\Lib\site-packages\urllib3\connection.py", line 445, in request
2025-10-12T19:33:30:     self.endheaders()
2025-10-12T19:33:30:     ~~~~~~~~~~~~~~~^^
2025-10-12T19:33:30:   File "C:\USERS\SAHAN\APPDATA\LOCAL\PROGRAMS\PYTHON\PYTHON313\Lib\http\client.py", line 1333, in endheaders
2025-10-12T19:33:30:     self._send_output(message_body, encode_chunked=encode_chunked)
2025-10-12T19:33:30:     ~~~~~~~~~~~~~~~~~^^^^^^^^^^^^^^^^^^^^^^^^^^^^^^^^^^^^^^^^^^^^^
2025-10-12T19:33:30:   File "C:\USERS\SAHAN\APPDATA\LOCAL\PROGRAMS\PYTHON\PYTHON313\Lib\http\client.py", line 1093, in _send_output
2025-10-12T19:33:30:     self.send(msg)
2025-10-12T19:33:30:     ~~~~~~~~~^^^^^
2025-10-12T19:33:30:   File "C:\USERS\SAHAN\APPDATA\LOCAL\PROGRAMS\PYTHON\PYTHON313\Lib\http\client.py", line 1037, in send
2025-10-12T19:33:30:     self.connect()
2025-10-12T19:33:30:     ~~~~~~~~~~~~^^
2025-10-12T19:33:30:   File "C:\USERS\SAHAN\APPDATA\LOCAL\PROGRAMS\PYTHON\PYTHON313\Lib\site-packages\urllib3\connection.py", line 276, in connect
2025-10-12T19:33:30:     self.sock = self._new_conn()
2025-10-12T19:33:30:                 ~~~~~~~~~~~~~~^^
2025-10-12T19:33:30:   File "C:\USERS\SAHAN\APPDATA\LOCAL\PROGRAMS\PYTHON\PYTHON313\Lib\site-packages\urllib3\connection.py", line 213, in _new_conn
2025-10-12T19:33:30:     raise NewConnectionError(
2025-10-12T19:33:30:         self, f"Failed to establish a new connection: {e}"
2025-10-12T19:33:30:     ) from e
2025-10-12T19:33:30: urllib3.exceptions.NewConnectionError: <urllib3.connection.HTTPConnection object at 0x0000020E7422AE00>: Failed to establish a new connection: [WinError 10061] No connection could be made because the target machine actively refused it
2025-10-12T19:33:30: 
2025-10-12T19:33:30: The above exception was the direct cause of the following exception:
2025-10-12T19:33:30: 
2025-10-12T19:33:30: Traceback (most recent call last):
2025-10-12T19:33:30:   File "C:\Users\Sahan\Dark\Promise\genApp\backend\gen.py", line 45, in __init__
2025-10-12T19:33:30:     img = self.extract_images(count = 6)
2025-10-12T19:33:30:   File "C:\Users\Sahan\Dark\Promise\genApp\backend\gen.py", line 75, in extract_images
2025-10-12T19:33:30:     self.driver.switch_to.default_content()  # Switch back to the main content
2025-10-12T19:33:30:     ~~~~~~~~~~~~~~~~~~~~~~~~~~~~~~~~~~~~~^^
2025-10-12T19:33:30:   File "C:\USERS\SAHAN\APPDATA\LOCAL\PROGRAMS\PYTHON\PYTHON313\Lib\site-packages\selenium\webdriver\remote\switch_to.py", line 66, in default_content
2025-10-12T19:33:30:     self._driver.execute(Command.SWITCH_TO_FRAME, {"id": None})
2025-10-12T19:33:30:     ~~~~~~~~~~~~~~~~~~~~^^^^^^^^^^^^^^^^^^^^^^^^^^^^^^^^^^^^^^^
2025-10-12T19:33:30:   File "C:\USERS\SAHAN\APPDATA\LOCAL\PROGRAMS\PYTHON\PYTHON313\Lib\site-packages\selenium\webdriver\remote\webdriver.py", line 451, in execute
2025-10-12T19:33:30:     response = cast(RemoteConnection, self.command_executor).execute(driver_command, params)
2025-10-12T19:33:30:   File "C:\USERS\SAHAN\APPDATA\LOCAL\PROGRAMS\PYTHON\PYTHON313\Lib\site-packages\selenium\webdriver\remote\remote_connection.py", line 404, in execute
2025-10-12T19:33:30:     return self._request(command_info[0], url, body=data)
2025-10-12T19:33:30:            ~~~~~~~~~~~~~^^^^^^^^^^^^^^^^^^^^^^^^^^^^^^^^^
2025-10-12T19:33:30:   File "C:\USERS\SAHAN\APPDATA\LOCAL\PROGRAMS\PYTHON\PYTHON313\Lib\site-packages\selenium\webdriver\remote\remote_connection.py", line 428, in _request
2025-10-12T19:33:30:     response = self._conn.request(method, url, body=body, headers=headers, timeout=self._client_config.timeout)
2025-10-12T19:33:30:   File "C:\USERS\SAHAN\APPDATA\LOCAL\PROGRAMS\PYTHON\PYTHON313\Lib\site-packages\urllib3\_request_methods.py", line 143, in request
2025-10-12T19:33:30:     return self.request_encode_body(
2025-10-12T19:33:30:            ~~~~~~~~~~~~~~~~~~~~~~~~^
2025-10-12T19:33:30:         method, url, fields=fields, headers=headers, **urlopen_kw
2025-10-12T19:33:30:         ^^^^^^^^^^^^^^^^^^^^^^^^^^^^^^^^^^^^^^^^^^^^^^^^^^^^^^^^^
2025-10-12T19:33:30:     )
2025-10-12T19:33:30:     ^
2025-10-12T19:33:30:   File "C:\USERS\SAHAN\APPDATA\LOCAL\PROGRAMS\PYTHON\PYTHON313\Lib\site-packages\urllib3\_request_methods.py", line 278, in request_encode_body
2025-10-12T19:33:30:     return self.urlopen(method, url, **extra_kw)
2025-10-12T19:33:30:            ~~~~~~~~~~~~^^^^^^^^^^^^^^^^^^^^^^^^^
2025-10-12T19:33:30:   File "C:\USERS\SAHAN\APPDATA\LOCAL\PROGRAMS\PYTHON\PYTHON313\Lib\site-packages\urllib3\poolmanager.py", line 443, in urlopen
2025-10-12T19:33:30:     response = conn.urlopen(method, u.request_uri, **kw)
2025-10-12T19:33:30:   File "C:\USERS\SAHAN\APPDATA\LOCAL\PROGRAMS\PYTHON\PYTHON313\Lib\site-packages\urllib3\connectionpool.py", line 871, in urlopen
2025-10-12T19:33:30:     return self.urlopen(
2025-10-12T19:33:30:            ~~~~~~~~~~~~^
2025-10-12T19:33:30:         method,
2025-10-12T19:33:30:         ^^^^^^^
2025-10-12T19:33:30:     ...<13 lines>...
2025-10-12T19:33:30:         **response_kw,
2025-10-12T19:33:30:         ^^^^^^^^^^^^^^
2025-10-12T19:33:30:     )
2025-10-12T19:33:30:     ^
2025-10-12T19:33:30:   File "C:\USERS\SAHAN\APPDATA\LOCAL\PROGRAMS\PYTHON\PYTHON313\Lib\site-packages\urllib3\connectionpool.py", line 871, in urlopen
2025-10-12T19:33:30:     return self.urlopen(
2025-10-12T19:33:30:            ~~~~~~~~~~~~^
2025-10-12T19:33:30:         method,
2025-10-12T19:33:30:         ^^^^^^^
2025-10-12T19:33:30:     ...<13 lines>...
2025-10-12T19:33:30:         **response_kw,
2025-10-12T19:33:30:         ^^^^^^^^^^^^^^
2025-10-12T19:33:30:     )
2025-10-12T19:33:30:     ^
2025-10-12T19:33:30:   File "C:\USERS\SAHAN\APPDATA\LOCAL\PROGRAMS\PYTHON\PYTHON313\Lib\site-packages\urllib3\connectionpool.py", line 871, in urlopen
2025-10-12T19:33:30:     return self.urlopen(
2025-10-12T19:33:30:            ~~~~~~~~~~~~^
2025-10-12T19:33:30:         method,
2025-10-12T19:33:30:         ^^^^^^^
2025-10-12T19:33:30:     ...<13 lines>...
2025-10-12T19:33:30:         **response_kw,
2025-10-12T19:33:30:         ^^^^^^^^^^^^^^
2025-10-12T19:33:30:     )
2025-10-12T19:33:30:     ^
2025-10-12T19:33:30:   File "C:\USERS\SAHAN\APPDATA\LOCAL\PROGRAMS\PYTHON\PYTHON313\Lib\site-packages\urllib3\connectionpool.py", line 841, in urlopen
2025-10-12T19:33:30:     retries = retries.increment(
2025-10-12T19:33:30:         method, url, error=new_e, _pool=self, _stacktrace=sys.exc_info()[2]
2025-10-12T19:33:30:     )
2025-10-12T19:33:30:   File "C:\USERS\SAHAN\APPDATA\LOCAL\PROGRAMS\PYTHON\PYTHON313\Lib\site-packages\urllib3\util\retry.py", line 519, in increment
2025-10-12T19:33:30:     raise MaxRetryError(_pool, url, reason) from reason  # type: ignore[arg-type]
2025-10-12T19:33:30:     ^^^^^^^^^^^^^^^^^^^^^^^^^^^^^^^^^^^^^^^^^^^^^^^^^^^
2025-10-12T19:33:30: urllib3.exceptions.MaxRetryError: HTTPConnectionPool(host='localhost', port=21479): Max retries exceeded with url: /session/132d00879998bce1c7e0febabacab2e3/frame (Caused by NewConnectionError('<urllib3.connection.HTTPConnection object at 0x0000020E7422AE00>: Failed to establish a new connection: [WinError 10061] No connection could be made because the target machine actively refused it'))
2025-10-12T19:34:47: Traceback (most recent call last):
2025-10-12T19:34:47:   File "C:\USERS\SAHAN\APPDATA\LOCAL\PROGRAMS\PYTHON\PYTHON313\Lib\site-packages\urllib3\connection.py", line 198, in _new_conn
2025-10-12T19:34:47:     sock = connection.create_connection(
2025-10-12T19:34:47:         (self._dns_host, self.port),
2025-10-12T19:34:47:     ...<2 lines>...
2025-10-12T19:34:47:         socket_options=self.socket_options,
2025-10-12T19:34:47:     )
2025-10-12T19:34:47:   File "C:\USERS\SAHAN\APPDATA\LOCAL\PROGRAMS\PYTHON\PYTHON313\Lib\site-packages\urllib3\util\connection.py", line 85, in create_connection
2025-10-12T19:34:47:     raise err
2025-10-12T19:34:47:   File "C:\USERS\SAHAN\APPDATA\LOCAL\PROGRAMS\PYTHON\PYTHON313\Lib\site-packages\urllib3\util\connection.py", line 73, in create_connection
2025-10-12T19:34:47:     sock.connect(sa)
2025-10-12T19:34:47:     ~~~~~~~~~~~~^^^^
2025-10-12T19:34:47: ConnectionRefusedError: [WinError 10061] No connection could be made because the target machine actively refused it
2025-10-12T19:34:47: 
2025-10-12T19:34:47: The above exception was the direct cause of the following exception:
2025-10-12T19:34:47: 
2025-10-12T19:34:47: Traceback (most recent call last):
2025-10-12T19:34:47:   File "C:\USERS\SAHAN\APPDATA\LOCAL\PROGRAMS\PYTHON\PYTHON313\Lib\site-packages\urllib3\connectionpool.py", line 787, in urlopen
2025-10-12T19:34:47:     response = self._make_request(
2025-10-12T19:34:47:         conn,
2025-10-12T19:34:47:     ...<10 lines>...
2025-10-12T19:34:47:         **response_kw,
2025-10-12T19:34:47:     )
2025-10-12T19:34:47:   File "C:\USERS\SAHAN\APPDATA\LOCAL\PROGRAMS\PYTHON\PYTHON313\Lib\site-packages\urllib3\connectionpool.py", line 493, in _make_request
2025-10-12T19:34:47:     conn.request(
2025-10-12T19:34:47:     ~~~~~~~~~~~~^
2025-10-12T19:34:47:         method,
2025-10-12T19:34:47:         ^^^^^^^
2025-10-12T19:34:47:     ...<6 lines>...
2025-10-12T19:34:47:         enforce_content_length=enforce_content_length,
2025-10-12T19:34:47:         ^^^^^^^^^^^^^^^^^^^^^^^^^^^^^^^^^^^^^^^^^^^^^^
2025-10-12T19:34:47:     )
2025-10-12T19:34:47:     ^
2025-10-12T19:34:47:   File "C:\USERS\SAHAN\APPDATA\LOCAL\PROGRAMS\PYTHON\PYTHON313\Lib\site-packages\urllib3\connection.py", line 445, in request
2025-10-12T19:34:47:     self.endheaders()
2025-10-12T19:34:47:     ~~~~~~~~~~~~~~~^^
2025-10-12T19:34:47:   File "C:\USERS\SAHAN\APPDATA\LOCAL\PROGRAMS\PYTHON\PYTHON313\Lib\http\client.py", line 1333, in endheaders
2025-10-12T19:34:47:     self._send_output(message_body, encode_chunked=encode_chunked)
2025-10-12T19:34:47:     ~~~~~~~~~~~~~~~~~^^^^^^^^^^^^^^^^^^^^^^^^^^^^^^^^^^^^^^^^^^^^^
2025-10-12T19:34:47:   File "C:\USERS\SAHAN\APPDATA\LOCAL\PROGRAMS\PYTHON\PYTHON313\Lib\http\client.py", line 1093, in _send_output
2025-10-12T19:34:47:     self.send(msg)
2025-10-12T19:34:47:     ~~~~~~~~~^^^^^
2025-10-12T19:34:47:   File "C:\USERS\SAHAN\APPDATA\LOCAL\PROGRAMS\PYTHON\PYTHON313\Lib\http\client.py", line 1037, in send
2025-10-12T19:34:47:     self.connect()
2025-10-12T19:34:47:     ~~~~~~~~~~~~^^
2025-10-12T19:34:47:   File "C:\USERS\SAHAN\APPDATA\LOCAL\PROGRAMS\PYTHON\PYTHON313\Lib\site-packages\urllib3\connection.py", line 276, in connect
2025-10-12T19:34:47:     self.sock = self._new_conn()
2025-10-12T19:34:47:                 ~~~~~~~~~~~~~~^^
2025-10-12T19:34:47:   File "C:\USERS\SAHAN\APPDATA\LOCAL\PROGRAMS\PYTHON\PYTHON313\Lib\site-packages\urllib3\connection.py", line 213, in _new_conn
2025-10-12T19:34:47:     raise NewConnectionError(
2025-10-12T19:34:47:         self, f"Failed to establish a new connection: {e}"
2025-10-12T19:34:47:     ) from e
2025-10-12T19:34:47: urllib3.exceptions.NewConnectionError: <urllib3.connection.HTTPConnection object at 0x0000020E74851D00>: Failed to establish a new connection: [WinError 10061] No connection could be made because the target machine actively refused it
2025-10-12T19:34:47: 
2025-10-12T19:34:47: The above exception was the direct cause of the following exception:
2025-10-12T19:34:47: 
2025-10-12T19:34:47: Traceback (most recent call last):
2025-10-12T19:34:47:   File "C:\Users\Sahan\Dark\Promise\genApp\backend\gen.py", line 14, in __init__
2025-10-12T19:34:47:     self.driver.uc_open_with_reconnect('https://perchance.org', 1)
2025-10-12T19:34:47:     ~~~~~~~~~~~~~~~~~~~~~~~~~~~~~~~~~~^^^^^^^^^^^^^^^^^^^^^^^^^^^^
2025-10-12T19:34:47:   File "C:\USERS\SAHAN\APPDATA\LOCAL\PROGRAMS\PYTHON\PYTHON313\Lib\site-packages\seleniumbase\core\browser_launcher.py", line 5602, in <lambda>
2025-10-12T19:34:47:     lambda *args, **kwargs: uc_open_with_reconnect(
2025-10-12T19:34:47:                             ~~~~~~~~~~~~~~~~~~~~~~^
2025-10-12T19:34:47:         driver, *args, **kwargs
2025-10-12T19:34:47:         ^^^^^^^^^^^^^^^^^^^^^^^
2025-10-12T19:34:47:     )
2025-10-12T19:34:47:     ^
2025-10-12T19:34:47:   File "C:\USERS\SAHAN\APPDATA\LOCAL\PROGRAMS\PYTHON\PYTHON313\Lib\site-packages\seleniumbase\core\browser_launcher.py", line 560, in uc_open_with_reconnect
2025-10-12T19:34:47:     driver, driver.window_handles[-1], 2
2025-10-12T19:34:47:             ^^^^^^^^^^^^^^^^^^^^^
2025-10-12T19:34:47:   File "C:\USERS\SAHAN\APPDATA\LOCAL\PROGRAMS\PYTHON\PYTHON313\Lib\site-packages\seleniumbase\undetected\__init__.py", line 348, in __getattribute__
2025-10-12T19:34:47:     return super().__getattribute__(item)
2025-10-12T19:34:47:            ~~~~~~~~~~~~~~~~~~~~~~~~^^^^^^
2025-10-12T19:34:47:   File "C:\USERS\SAHAN\APPDATA\LOCAL\PROGRAMS\PYTHON\PYTHON313\Lib\site-packages\selenium\webdriver\remote\webdriver.py", line 636, in window_handles
2025-10-12T19:34:47:     return self.execute(Command.W3C_GET_WINDOW_HANDLES)["value"]
2025-10-12T19:34:47:            ~~~~~~~~~~~~^^^^^^^^^^^^^^^^^^^^^^^^^^^^^^^^
2025-10-12T19:34:47:   File "C:\USERS\SAHAN\APPDATA\LOCAL\PROGRAMS\PYTHON\PYTHON313\Lib\site-packages\selenium\webdriver\remote\webdriver.py", line 451, in execute
2025-10-12T19:34:47:     response = cast(RemoteConnection, self.command_executor).execute(driver_command, params)
2025-10-12T19:34:47:   File "C:\USERS\SAHAN\APPDATA\LOCAL\PROGRAMS\PYTHON\PYTHON313\Lib\site-packages\selenium\webdriver\remote\remote_connection.py", line 404, in execute
2025-10-12T19:34:47:     return self._request(command_info[0], url, body=data)
2025-10-12T19:34:47:            ~~~~~~~~~~~~~^^^^^^^^^^^^^^^^^^^^^^^^^^^^^^^^^
2025-10-12T19:34:47:   File "C:\USERS\SAHAN\APPDATA\LOCAL\PROGRAMS\PYTHON\PYTHON313\Lib\site-packages\selenium\webdriver\remote\remote_connection.py", line 428, in _request
2025-10-12T19:34:47:     response = self._conn.request(method, url, body=body, headers=headers, timeout=self._client_config.timeout)
2025-10-12T19:34:47:   File "C:\USERS\SAHAN\APPDATA\LOCAL\PROGRAMS\PYTHON\PYTHON313\Lib\site-packages\urllib3\_request_methods.py", line 135, in request
2025-10-12T19:34:47:     return self.request_encode_url(
2025-10-12T19:34:47:            ~~~~~~~~~~~~~~~~~~~~~~~^
2025-10-12T19:34:47:         method,
2025-10-12T19:34:47:         ^^^^^^^
2025-10-12T19:34:47:     ...<3 lines>...
2025-10-12T19:34:47:         **urlopen_kw,
2025-10-12T19:34:47:         ^^^^^^^^^^^^^
2025-10-12T19:34:47:     )
2025-10-12T19:34:47:     ^
2025-10-12T19:34:47:   File "C:\USERS\SAHAN\APPDATA\LOCAL\PROGRAMS\PYTHON\PYTHON313\Lib\site-packages\urllib3\_request_methods.py", line 182, in request_encode_url
2025-10-12T19:34:47:     return self.urlopen(method, url, **extra_kw)
2025-10-12T19:34:47:            ~~~~~~~~~~~~^^^^^^^^^^^^^^^^^^^^^^^^^
2025-10-12T19:34:47:   File "C:\USERS\SAHAN\APPDATA\LOCAL\PROGRAMS\PYTHON\PYTHON313\Lib\site-packages\urllib3\poolmanager.py", line 443, in urlopen
2025-10-12T19:34:47:     response = conn.urlopen(method, u.request_uri, **kw)
2025-10-12T19:34:47:   File "C:\USERS\SAHAN\APPDATA\LOCAL\PROGRAMS\PYTHON\PYTHON313\Lib\site-packages\urllib3\connectionpool.py", line 871, in urlopen
2025-10-12T19:34:47:     return self.urlopen(
2025-10-12T19:34:47:            ~~~~~~~~~~~~^
2025-10-12T19:34:47:         method,
2025-10-12T19:34:47:         ^^^^^^^
2025-10-12T19:34:47:     ...<13 lines>...
2025-10-12T19:34:47:         **response_kw,
2025-10-12T19:34:47:         ^^^^^^^^^^^^^^
2025-10-12T19:34:47:     )
2025-10-12T19:34:47:     ^
2025-10-12T19:34:47:   File "C:\USERS\SAHAN\APPDATA\LOCAL\PROGRAMS\PYTHON\PYTHON313\Lib\site-packages\urllib3\connectionpool.py", line 871, in urlopen
2025-10-12T19:34:47:     return self.urlopen(
2025-10-12T19:34:47:            ~~~~~~~~~~~~^
2025-10-12T19:34:47:         method,
2025-10-12T19:34:47:         ^^^^^^^
2025-10-12T19:34:47:     ...<13 lines>...
2025-10-12T19:34:47:         **response_kw,
2025-10-12T19:34:47:         ^^^^^^^^^^^^^^
2025-10-12T19:34:47:     )
2025-10-12T19:34:47:     ^
2025-10-12T19:34:47:   File "C:\USERS\SAHAN\APPDATA\LOCAL\PROGRAMS\PYTHON\PYTHON313\Lib\site-packages\urllib3\connectionpool.py", line 871, in urlopen
2025-10-12T19:34:47:     return self.urlopen(
2025-10-12T19:34:47:            ~~~~~~~~~~~~^
2025-10-12T19:34:47:         method,
2025-10-12T19:34:47:         ^^^^^^^
2025-10-12T19:34:47:     ...<13 lines>...
2025-10-12T19:34:47:         **response_kw,
2025-10-12T19:34:47:         ^^^^^^^^^^^^^^
2025-10-12T19:34:47:     )
2025-10-12T19:34:47:     ^
2025-10-12T19:34:47:   File "C:\USERS\SAHAN\APPDATA\LOCAL\PROGRAMS\PYTHON\PYTHON313\Lib\site-packages\urllib3\connectionpool.py", line 841, in urlopen
2025-10-12T19:34:47:     retries = retries.increment(
2025-10-12T19:34:47:         method, url, error=new_e, _pool=self, _stacktrace=sys.exc_info()[2]
2025-10-12T19:34:47:     )
2025-10-12T19:34:47:   File "C:\USERS\SAHAN\APPDATA\LOCAL\PROGRAMS\PYTHON\PYTHON313\Lib\site-packages\urllib3\util\retry.py", line 519, in increment
2025-10-12T19:34:47:     raise MaxRetryError(_pool, url, reason) from reason  # type: ignore[arg-type]
2025-10-12T19:34:47:     ^^^^^^^^^^^^^^^^^^^^^^^^^^^^^^^^^^^^^^^^^^^^^^^^^^^
2025-10-12T19:34:47: urllib3.exceptions.MaxRetryError: HTTPConnectionPool(host='localhost', port=47211): Max retries exceeded with url: /session/4721a11cf59e611c6ee329d695027ed0/window/handles (Caused by NewConnectionError('<urllib3.connection.HTTPConnection object at 0x0000020E74851D00>: Failed to establish a new connection: [WinError 10061] No connection could be made because the target machine actively refused it'))
2025-10-12T19:36:08: INFO:werkzeug:WARNING: This is a development server. Do not use it in a production deployment. Use a production WSGI server instead.
2025-10-12T19:36:08:  * Running on all addresses (0.0.0.0)
2025-10-12T19:36:08:  * Running on http://127.0.0.1:5002
2025-10-12T19:36:08:  * Running on http://192.168.1.2:5002
2025-10-12T19:36:08: INFO:werkzeug:Press CTRL+C to quit
2025-10-12T19:53:02: INFO:firestore_service:Firestore service initialized for project: image-genie-ff577
2025-10-12T19:53:02: INFO:in_memory_store:In-memory token store initialized
2025-10-12T19:54:41: Traceback (most recent call last):
2025-10-12T19:54:41:   File "C:\Users\Sahan\Dark\Promise\genApp\backend\gen.py", line 20, in __init__
2025-10-12T19:54:41:     self.driver.execute_script("window.localStorage.setItem('sensitiveContentVisibility', 'warn');")
2025-10-12T19:54:41:     ~~~~~~~~~~~~~~~~~~~~~~~~~~^^^^^^^^^^^^^^^^^^^^^^^^^^^^^^^^^^^^^^^^^^^^^^^^^^^^^^^^^^^^^^^^^^^^^^
2025-10-12T19:54:41:   File "C:\USERS\SAHAN\APPDATA\LOCAL\PROGRAMS\PYTHON\PYTHON313\Lib\site-packages\selenium\webdriver\remote\webdriver.py", line 551, in execute_script
2025-10-12T19:54:41:     return self.execute(command, {"script": script, "args": converted_args})["value"]
2025-10-12T19:54:41:            ~~~~~~~~~~~~^^^^^^^^^^^^^^^^^^^^^^^^^^^^^^^^^^^^^^^^^^^^^^^^^^^^^
2025-10-12T19:54:41:   File "C:\USERS\SAHAN\APPDATA\LOCAL\PROGRAMS\PYTHON\PYTHON313\Lib\site-packages\selenium\webdriver\remote\webdriver.py", line 454, in execute
2025-10-12T19:54:41:     self.error_handler.check_response(response)
2025-10-12T19:54:41:     ~~~~~~~~~~~~~~~~~~~~~~~~~~~~~~~~~^^^^^^^^^^
2025-10-12T19:54:41:   File "C:\USERS\SAHAN\APPDATA\LOCAL\PROGRAMS\PYTHON\PYTHON313\Lib\site-packages\selenium\webdriver\remote\errorhandler.py", line 232, in check_response
2025-10-12T19:54:41:     raise exception_class(message, screen, stacktrace)
2025-10-12T19:54:41: selenium.common.exceptions.NoSuchWindowException: Message: no such window: target window already closed
2025-10-12T19:54:41: from unknown error: web view not found
2025-10-12T19:54:41:   (Session info: chrome=141.0.7390.66)
2025-10-12T19:54:41: Stacktrace:
2025-10-12T19:54:41: 	GetHandleVerifier [0x0x7ff76e619f25+80677]
2025-10-12T19:54:41: 	GetHandleVerifier [0x0x7ff76e619f80+80768]
2025-10-12T19:54:41: 	(No symbol) [0x0x7ff76e3c02bf]
2025-10-12T19:54:41: 	(No symbol) [0x0x7ff76e398041]
2025-10-12T19:54:41: 	(No symbol) [0x0x7ff76e448b8e]
2025-10-12T19:54:41: 	(No symbol) [0x0x7ff76e4692d2]
2025-10-12T19:54:41: 	(No symbol) [0x0x7ff76e4412e3]
2025-10-12T19:54:41: 	(No symbol) [0x0x7ff76e409770]
2025-10-12T19:54:41: 	(No symbol) [0x0x7ff76e40a5a3]
2025-10-12T19:54:41: 	GetHandleVerifier [0x0x7ff76e8f817d+3087741]
2025-10-12T19:54:41: 	GetHandleVerifier [0x0x7ff76e8f223a+3063354]
2025-10-12T19:54:41: 	GetHandleVerifier [0x0x7ff76e9132c5+3198661]
2025-10-12T19:54:41: 	GetHandleVerifier [0x0x7ff76e63412e+187694]
2025-10-12T19:54:41: 	GetHandleVerifier [0x0x7ff76e63b20f+216591]
2025-10-12T19:54:41: 	GetHandleVerifier [0x0x7ff76e622ee4+117476]
2025-10-12T19:54:41: 	GetHandleVerifier [0x0x7ff76e62309f+117919]
2025-10-12T19:54:41: 	GetHandleVerifier [0x0x7ff76e6091a8+11688]
2025-10-12T19:54:41: 	BaseThreadInitThunk [0x0x7ffa4d61e8d7+23]
2025-10-12T19:54:41: 	RtlUserThreadStart [0x0x7ffa4e968d9c+44]
2025-10-12T19:54:41: 
2025-10-12T19:59:42: INFO:werkzeug:
2025-10-12T19:59:42: WARNING: This is a development server. Do not use it in a production deployment. Use a production WSGI server instead.
2025-10-12T19:59:42:  * Running on all addresses (0.0.0.0)
2025-10-12T19:59:42:  * Running on http://127.0.0.1:5002
2025-10-12T19:59:42:  * Running on http://192.168.1.2:5002
2025-10-12T19:59:42: INFO:werkzeug:Press CTRL+C to quit
2025-10-12T20:00:38: INFO:werkzeug:127.0.0.1 - - [12/Oct/2025 20:00:38] "GET /api/health HTTP/1.1" 200 -
2025-10-12T20:05:01: INFO:werkzeug:127.0.0.1 - - [12/Oct/2025 20:05:01] "GET /api/health HTTP/1.1" 200 -
2025-10-12T20:05:19: INFO:werkzeug:127.0.0.1 - - [12/Oct/2025 20:05:19] "GET /api/health-generate HTTP/1.1" 200 -
2025-10-12T20:05:19: Exception in thread 
2025-10-12T20:05:19: Thread-1 (gen_worker):
2025-10-12T20:05:19: Traceback (most recent call last):
2025-10-12T20:05:19:   File "C:\USERS\SAHAN\APPDATA\LOCAL\PROGRAMS\PYTHON\PYTHON313\Lib\threading.py", line 1041, in _bootstrap_inner
2025-10-12T20:05:19:     self.run()
2025-10-12T20:05:19:     ~~~~~~~~^^
2025-10-12T20:05:19:   File "C:\USERS\SAHAN\APPDATA\LOCAL\PROGRAMS\PYTHON\PYTHON313\Lib\threading.py", line 992, in run
2025-10-12T20:05:19:     self._target(*self._args, **self._kwargs)
2025-10-12T20:05:19:     ~~~~~~~~~~~~^^^^^^^^^^^^^^^^^^^^^^^^^^^^^
2025-10-12T20:05:19:   File "C:\Users\Sahan\Dark\Promise\genApp\backend\server.py", line 602, in gen_worker
2025-10-12T20:05:19:     image = gen.play(prompt, style)
2025-10-12T20:05:19:   File "C:\Users\Sahan\Dark\Promise\genApp\backend\gen.py", line 116, in play
2025-10-12T20:05:19:     self.set_style(style)  # Set default style
2025-10-12T20:05:19:     ~~~~~~~~~~~~~~^^^^^^^
2025-10-12T20:05:19:   File "C:\Users\Sahan\Dark\Promise\genApp\backend\gen.py", line 103, in set_style
2025-10-12T20:05:19:     style_select = self.driver.find_element("xpath", "/html/body/div[1]/div[1]/div[4]/div/div[2]/select")
2025-10-12T20:05:19:   File "C:\USERS\SAHAN\APPDATA\LOCAL\PROGRAMS\PYTHON\PYTHON313\Lib\site-packages\seleniumbase\core\sb_driver.py", line 28, in find_element
2025-10-12T20:05:19:     return self.driver.default_find_element(by=by, value=value)
2025-10-12T20:05:19:            ~~~~~~~~~~~~~~~~~~~~~~~~~~~~~~~~^^^^^^^^^^^^^^^^^^^^
2025-10-12T20:05:19:   File "C:\USERS\SAHAN\APPDATA\LOCAL\PROGRAMS\PYTHON\PYTHON313\Lib\site-packages\selenium\webdriver\remote\webdriver.py", line 922, in find_element
2025-10-12T20:05:19:     return self.execute(Command.FIND_ELEMENT, {"using": by, "value": value})["value"]
2025-10-12T20:05:19:            ~~~~~~~~~~~~^^^^^^^^^^^^^^^^^^^^^^^^^^^^^^^^^^^^^^^^^^^^^^^^^^^^^
2025-10-12T20:05:19:   File "C:\USERS\SAHAN\APPDATA\LOCAL\PROGRAMS\PYTHON\PYTHON313\Lib\site-packages\selenium\webdriver\remote\webdriver.py", line 454, in execute
2025-10-12T20:05:19:     self.error_handler.check_response(response)
2025-10-12T20:05:19:     ~~~~~~~~~~~~~~~~~~~~~~~~~~~~~~~~~^^^^^^^^^^
2025-10-12T20:05:19:   File "C:\USERS\SAHAN\APPDATA\LOCAL\PROGRAMS\PYTHON\PYTHON313\Lib\site-packages\selenium\webdriver\remote\errorhandler.py", line 232, in check_response
2025-10-12T20:05:19:     raise exception_class(message, screen, stacktrace)
2025-10-12T20:05:19: selenium.common.exceptions.NoSuchWindowException: Message: no such window: target window already closed
2025-10-12T20:05:19: from unknown error: web view not found
2025-10-12T20:05:19:   (Session info: chrome=141.0.7390.66)
2025-10-12T20:05:19: Stacktrace:
2025-10-12T20:05:19: 	GetHandleVerifier [0x0x7ff76e619f25+80677]
2025-10-12T20:05:19: 	GetHandleVerifier [0x0x7ff76e619f80+80768]
2025-10-12T20:05:19: 	(No symbol) [0x0x7ff76e3c02bf]
2025-10-12T20:05:19: 	(No symbol) [0x0x7ff76e398041]
2025-10-12T20:05:19: 	(No symbol) [0x0x7ff76e448b8e]
2025-10-12T20:05:19: 	(No symbol) [0x0x7ff76e4692d2]
2025-10-12T20:05:19: 	(No symbol) [0x0x7ff76e4412e3]
2025-10-12T20:05:19: 	(No symbol) [0x0x7ff76e409770]
2025-10-12T20:05:19: 	(No symbol) [0x0x7ff76e40a5a3]
2025-10-12T20:05:19: 	GetHandleVerifier [0x0x7ff76e8f817d+3087741]
2025-10-12T20:05:19: 	GetHandleVerifier [0x0x7ff76e8f223a+3063354]
2025-10-12T20:05:19: 	GetHandleVerifier [0x0x7ff76e9132c5+3198661]
2025-10-12T20:05:19: 	GetHandleVerifier [0x0x7ff76e63412e+187694]
2025-10-12T20:05:19: 	GetHandleVerifier [0x0x7ff76e63b20f+216591]
2025-10-12T20:05:19: 	GetHandleVerifier [0x0x7ff76e622ee4+117476]
2025-10-12T20:05:19: 	GetHandleVerifier [0x0x7ff76e62309f+117919]
2025-10-12T20:05:19: 	GetHandleVerifier [0x0x7ff76e6091a8+11688]
2025-10-12T20:05:19: 	BaseThreadInitThunk [0x0x7ffa4d61e8d7+23]
2025-10-12T20:05:19: 	RtlUserThreadStart [0x0x7ffa4e968d9c+44]
2025-10-12T20:05:19: 
2025-10-12T20:05:38: INFO:werkzeug:127.0.0.1 - - [12/Oct/2025 20:05:38] "GET /api/health-generate HTTP/1.1" 200 -
2025-10-12T20:05:38: Exception in thread 
2025-10-12T20:05:38: Thread-2 (gen_worker):
2025-10-12T20:05:38: Traceback (most recent call last):
2025-10-12T20:05:38:   File "C:\USERS\SAHAN\APPDATA\LOCAL\PROGRAMS\PYTHON\PYTHON313\Lib\threading.py", line 1041, in _bootstrap_inner
2025-10-12T20:05:38:     self.run()
2025-10-12T20:05:38:     ~~~~~~~~^^
2025-10-12T20:05:38:   File "C:\USERS\SAHAN\APPDATA\LOCAL\PROGRAMS\PYTHON\PYTHON313\Lib\threading.py", line 992, in run
2025-10-12T20:05:38:     self._target(*self._args, **self._kwargs)
2025-10-12T20:05:38:     ~~~~~~~~~~~~^^^^^^^^^^^^^^^^^^^^^^^^^^^^^
2025-10-12T20:05:38:   File "C:\Users\Sahan\Dark\Promise\genApp\backend\server.py", line 602, in gen_worker
2025-10-12T20:05:38:     image = gen.play(prompt, style)
2025-10-12T20:05:38:   File "C:\Users\Sahan\Dark\Promise\genApp\backend\gen.py", line 116, in play
2025-10-12T20:05:38:     self.set_style(style)  # Set default style
2025-10-12T20:05:38:     ~~~~~~~~~~~~~~^^^^^^^
2025-10-12T20:05:38:   File "C:\Users\Sahan\Dark\Promise\genApp\backend\gen.py", line 103, in set_style
2025-10-12T20:05:38:     style_select = self.driver.find_element("xpath", "/html/body/div[1]/div[1]/div[4]/div/div[2]/select")
2025-10-12T20:05:38:   File "C:\USERS\SAHAN\APPDATA\LOCAL\PROGRAMS\PYTHON\PYTHON313\Lib\site-packages\seleniumbase\core\sb_driver.py", line 28, in find_element
2025-10-12T20:05:38:     return self.driver.default_find_element(by=by, value=value)
2025-10-12T20:05:38:            ~~~~~~~~~~~~~~~~~~~~~~~~~~~~~~~~^^^^^^^^^^^^^^^^^^^^
2025-10-12T20:05:38:   File "C:\USERS\SAHAN\APPDATA\LOCAL\PROGRAMS\PYTHON\PYTHON313\Lib\site-packages\selenium\webdriver\remote\webdriver.py", line 922, in find_element
2025-10-12T20:05:38:     return self.execute(Command.FIND_ELEMENT, {"using": by, "value": value})["value"]
2025-10-12T20:05:38:            ~~~~~~~~~~~~^^^^^^^^^^^^^^^^^^^^^^^^^^^^^^^^^^^^^^^^^^^^^^^^^^^^^
2025-10-12T20:05:38:   File "C:\USERS\SAHAN\APPDATA\LOCAL\PROGRAMS\PYTHON\PYTHON313\Lib\site-packages\selenium\webdriver\remote\webdriver.py", line 454, in execute
2025-10-12T20:05:38:     self.error_handler.check_response(response)
2025-10-12T20:05:38:     ~~~~~~~~~~~~~~~~~~~~~~~~~~~~~~~~~^^^^^^^^^^
2025-10-12T20:05:38:   File "C:\USERS\SAHAN\APPDATA\LOCAL\PROGRAMS\PYTHON\PYTHON313\Lib\site-packages\selenium\webdriver\remote\errorhandler.py", line 232, in check_response
2025-10-12T20:05:38:     raise exception_class(message, screen, stacktrace)
2025-10-12T20:05:38: selenium.common.exceptions.NoSuchWindowException: Message: no such window: target window already closed
2025-10-12T20:05:38: from unknown error: web view not found
2025-10-12T20:05:38:   (Session info: chrome=141.0.7390.66)
2025-10-12T20:05:38: Stacktrace:
2025-10-12T20:05:38: 	GetHandleVerifier [0x0x7ff76e619f25+80677]
2025-10-12T20:05:38: 	GetHandleVerifier [0x0x7ff76e619f80+80768]
2025-10-12T20:05:38: 	(No symbol) [0x0x7ff76e3c02bf]
2025-10-12T20:05:38: 	(No symbol) [0x0x7ff76e398041]
2025-10-12T20:05:38: 	(No symbol) [0x0x7ff76e448b8e]
2025-10-12T20:05:38: 	(No symbol) [0x0x7ff76e4692d2]
2025-10-12T20:05:38: 	(No symbol) [0x0x7ff76e4412e3]
2025-10-12T20:05:38: 	(No symbol) [0x0x7ff76e409770]
2025-10-12T20:05:38: 	(No symbol) [0x0x7ff76e40a5a3]
2025-10-12T20:05:38: 	GetHandleVerifier [0x0x7ff76e8f817d+3087741]
2025-10-12T20:05:38: 	GetHandleVerifier [0x0x7ff76e8f223a+3063354]
2025-10-12T20:05:38: 	GetHandleVerifier [0x0x7ff76e9132c5+3198661]
2025-10-12T20:05:38: 	GetHandleVerifier [0x0x7ff76e63412e+187694]
2025-10-12T20:05:38: 	GetHandleVerifier [0x0x7ff76e63b20f+216591]
2025-10-12T20:05:38: 	GetHandleVerifier [0x0x7ff76e622ee4+117476]
2025-10-12T20:05:38: 	GetHandleVerifier [0x0x7ff76e62309f+117919]
2025-10-12T20:05:38: 	GetHandleVerifier [0x0x7ff76e6091a8+11688]
2025-10-12T20:05:38: 	BaseThreadInitThunk [0x0x7ffa4d61e8d7+23]
2025-10-12T20:05:38: 	RtlUserThreadStart [0x0x7ffa4e968d9c+44]
2025-10-12T20:05:38: 
2025-10-12T20:13:29: INFO:firestore_service:Firestore service initialized for project: image-genie-ff577
2025-10-12T20:13:29: INFO:in_memory_store:In-memory token store initialized
2025-10-12T20:14:27: INFO:werkzeug:WARNING: This is a development server. Do not use it in a production deployment. Use a production WSGI server instead.
2025-10-12T20:14:27:  * Running on all addresses (0.0.0.0)
2025-10-12T20:14:27:  * Running on http://127.0.0.1:5002
2025-10-12T20:14:27:  * Running on http://192.168.1.2:5002
2025-10-12T20:14:27: INFO:werkzeug:Press CTRL+C to quit
2025-10-12T20:15:31: INFO:werkzeug:127.0.0.1 - - [12/Oct/2025 20:15:31] "GET /api/health HTTP/1.1" 200 -
2025-10-12T20:20:32: INFO:firestore_service:Firestore service initialized for project: image-genie-ff577
2025-10-12T20:20:32: INFO:in_memory_store:In-memory token store initialized
2025-10-12T20:20:55: Traceback (most recent call last):
2025-10-12T20:20:55:   File "C:\Users\Sahan\Dark\Promise\genApp\backend\gen.py", line 20, in __init__
2025-10-12T20:20:55:     self.driver.execute_script("window.localStorage.setItem('sensitiveContentVisibility', 'warn');")
2025-10-12T20:20:55:     ~~~~~~~~~~~~~~~~~~~~~~~~~~^^^^^^^^^^^^^^^^^^^^^^^^^^^^^^^^^^^^^^^^^^^^^^^^^^^^^^^^^^^^^^^^^^^^^^
2025-10-12T20:20:55:   File "C:\USERS\SAHAN\APPDATA\LOCAL\PROGRAMS\PYTHON\PYTHON313\Lib\site-packages\selenium\webdriver\remote\webdriver.py", line 551, in execute_script
2025-10-12T20:20:55:     return self.execute(command, {"script": script, "args": converted_args})["value"]
2025-10-12T20:20:55:            ~~~~~~~~~~~~^^^^^^^^^^^^^^^^^^^^^^^^^^^^^^^^^^^^^^^^^^^^^^^^^^^^^
2025-10-12T20:20:55:   File "C:\USERS\SAHAN\APPDATA\LOCAL\PROGRAMS\PYTHON\PYTHON313\Lib\site-packages\selenium\webdriver\remote\webdriver.py", line 454, in execute
2025-10-12T20:20:55:     self.error_handler.check_response(response)
2025-10-12T20:20:55:     ~~~~~~~~~~~~~~~~~~~~~~~~~~~~~~~~~^^^^^^^^^^
2025-10-12T20:20:55:   File "C:\USERS\SAHAN\APPDATA\LOCAL\PROGRAMS\PYTHON\PYTHON313\Lib\site-packages\selenium\webdriver\remote\errorhandler.py", line 232, in check_response
2025-10-12T20:20:55:     raise exception_class(message, screen, stacktrace)
2025-10-12T20:20:55: selenium.common.exceptions.NoSuchWindowException: Message: no such window: target window already closed
2025-10-12T20:20:55: from unknown error: web view not found
2025-10-12T20:20:55:   (Session info: chrome=141.0.7390.66)
2025-10-12T20:20:55: Stacktrace:
2025-10-12T20:20:55: 	GetHandleVerifier [0x0x7ff76e619f25+80677]
2025-10-12T20:20:55: 	GetHandleVerifier [0x0x7ff76e619f80+80768]
2025-10-12T20:20:55: 	(No symbol) [0x0x7ff76e3c02bf]
2025-10-12T20:20:55: 	(No symbol) [0x0x7ff76e398041]
2025-10-12T20:20:55: 	(No symbol) [0x0x7ff76e448b8e]
2025-10-12T20:20:55: 	(No symbol) [0x0x7ff76e4692d2]
2025-10-12T20:20:55: 	(No symbol) [0x0x7ff76e4412e3]
2025-10-12T20:20:55: 	(No symbol) [0x0x7ff76e409770]
2025-10-12T20:20:55: 	(No symbol) [0x0x7ff76e40a5a3]
2025-10-12T20:20:55: 	GetHandleVerifier [0x0x7ff76e8f817d+3087741]
2025-10-12T20:20:55: 	GetHandleVerifier [0x0x7ff76e8f223a+3063354]
2025-10-12T20:20:55: 	GetHandleVerifier [0x0x7ff76e9132c5+3198661]
2025-10-12T20:20:55: 	GetHandleVerifier [0x0x7ff76e63412e+187694]
2025-10-12T20:20:55: 	GetHandleVerifier [0x0x7ff76e63b20f+216591]
2025-10-12T20:20:55: 	GetHandleVerifier [0x0x7ff76e622ee4+117476]
2025-10-12T20:20:55: 	GetHandleVerifier [0x0x7ff76e62309f+117919]
2025-10-12T20:20:55: 	GetHandleVerifier [0x0x7ff76e6091a8+11688]
2025-10-12T20:20:55: 	BaseThreadInitThunk [0x0x7ffa4d61e8d7+23]
2025-10-12T20:20:55: 	RtlUserThreadStart [0x0x7ffa4e968d9c+44]
2025-10-12T20:20:55: 
2025-10-12T20:20:56: INFO:werkzeug:
2025-10-12T20:20:56: WARNING: This is a development server. Do not use it in a production deployment. Use a production WSGI server instead.
2025-10-12T20:20:56:  * Running on all addresses (0.0.0.0)
2025-10-12T20:20:56:  * Running on http://127.0.0.1:5002
2025-10-12T20:20:56:  * Running on http://192.168.1.2:5002
2025-10-12T20:20:56: INFO:werkzeug:Press CTRL+C to quit
2025-10-12T20:23:31: INFO:werkzeug:127.0.0.1 - - [12/Oct/2025 20:23:31] "GET /api/health HTTP/1.1" 200 -
2025-10-12T20:24:08: INFO:werkzeug:127.0.0.1 - - [12/Oct/2025 20:24:08] "GET /api/health-generate HTTP/1.1" 200 -
2025-10-12T20:24:08: Exception in thread Thread-1 (gen_worker):
2025-10-12T20:24:08: Traceback (most recent call last):
2025-10-12T20:24:08:   File "C:\Users\Sahan\Dark\Promise\genApp\backend\server.py", line 645, in gen_worker
2025-10-12T20:24:08:     image = gen.play(prompt, style)
2025-10-12T20:24:08:   File "C:\Users\Sahan\Dark\Promise\genApp\backend\gen.py", line 116, in play
2025-10-12T20:24:08:     self.set_style(style)  # Set default style
2025-10-12T20:24:08:     ~~~~~~~~~~~~~~^^^^^^^
2025-10-12T20:24:08:   File "C:\Users\Sahan\Dark\Promise\genApp\backend\gen.py", line 103, in set_style
2025-10-12T20:24:08:     style_select = self.driver.find_element("xpath", "/html/body/div[1]/div[1]/div[4]/div/div[2]/select")
2025-10-12T20:24:08:   File "C:\USERS\SAHAN\APPDATA\LOCAL\PROGRAMS\PYTHON\PYTHON313\Lib\site-packages\seleniumbase\core\sb_driver.py", line 28, in find_element
2025-10-12T20:24:08:     return self.driver.default_find_element(by=by, value=value)
2025-10-12T20:24:08:            ~~~~~~~~~~~~~~~~~~~~~~~~~~~~~~~~^^^^^^^^^^^^^^^^^^^^
2025-10-12T20:24:08:   File "C:\USERS\SAHAN\APPDATA\LOCAL\PROGRAMS\PYTHON\PYTHON313\Lib\site-packages\selenium\webdriver\remote\webdriver.py", line 922, in find_element
2025-10-12T20:24:08:     return self.execute(Command.FIND_ELEMENT, {"using": by, "value": value})["value"]
2025-10-12T20:24:08:            ~~~~~~~~~~~~^^^^^^^^^^^^^^^^^^^^^^^^^^^^^^^^^^^^^^^^^^^^^^^^^^^^^
2025-10-12T20:24:08:   File "C:\USERS\SAHAN\APPDATA\LOCAL\PROGRAMS\PYTHON\PYTHON313\Lib\site-packages\selenium\webdriver\remote\webdriver.py", line 454, in execute
2025-10-12T20:24:08:     self.error_handler.check_response(response)
2025-10-12T20:24:08:     ~~~~~~~~~~~~~~~~~~~~~~~~~~~~~~~~~^^^^^^^^^^
2025-10-12T20:24:08:   File "C:\USERS\SAHAN\APPDATA\LOCAL\PROGRAMS\PYTHON\PYTHON313\Lib\site-packages\selenium\webdriver\remote\errorhandler.py", line 232, in check_response
2025-10-12T20:24:08:     raise exception_class(message, screen, stacktrace)
2025-10-12T20:24:08: selenium.common.exceptions.NoSuchWindowException: Message: no such window: target window already closed
2025-10-12T20:24:08: from unknown error: web view not found
2025-10-12T20:24:08:   (Session info: chrome=141.0.7390.66)
2025-10-12T20:24:08: Stacktrace:
2025-10-12T20:24:08: 	GetHandleVerifier [0x0x7ff76e619f25+80677]
2025-10-12T20:24:08: 	GetHandleVerifier [0x0x7ff76e619f80+80768]
2025-10-12T20:24:08: 	(No symbol) [0x0x7ff76e3c02bf]
2025-10-12T20:24:08: 	(No symbol) [0x0x7ff76e398041]
2025-10-12T20:24:08: 	(No symbol) [0x0x7ff76e448b8e]
2025-10-12T20:24:08: 	(No symbol) [0x0x7ff76e4692d2]
2025-10-12T20:24:08: 	(No symbol) [0x0x7ff76e4412e3]
2025-10-12T20:24:08: 	(No symbol) [0x0x7ff76e409770]
2025-10-12T20:24:08: 	(No symbol) [0x0x7ff76e40a5a3]
2025-10-12T20:24:08: 	GetHandleVerifier [0x0x7ff76e8f817d+3087741]
2025-10-12T20:24:08: 	GetHandleVerifier [0x0x7ff76e8f223a+3063354]
2025-10-12T20:24:08: 	GetHandleVerifier [0x0x7ff76e9132c5+3198661]
2025-10-12T20:24:08: 	GetHandleVerifier [0x0x7ff76e63412e+187694]
2025-10-12T20:24:08: 	GetHandleVerifier [0x0x7ff76e63b20f+216591]
2025-10-12T20:24:08: 	GetHandleVerifier [0x0x7ff76e622ee4+117476]
2025-10-12T20:24:08: 	GetHandleVerifier [0x0x7ff76e62309f+117919]
2025-10-12T20:24:08: 	GetHandleVerifier [0x0x7ff76e6091a8+11688]
2025-10-12T20:24:08: 	BaseThreadInitThunk [0x0x7ffa4d61e8d7+23]
2025-10-12T20:24:08: 	RtlUserThreadStart [0x0x7ffa4e968d9c+44]
2025-10-12T20:24:08: 
2025-10-12T20:24:08: 
2025-10-12T20:24:08: During handling of the above exception, another exception occurred:
2025-10-12T20:24:08: 
2025-10-12T20:24:08: Traceback (most recent call last):
2025-10-12T20:24:08:   File "C:\USERS\SAHAN\APPDATA\LOCAL\PROGRAMS\PYTHON\PYTHON313\Lib\threading.py", line 1041, in _bootstrap_inner
2025-10-12T20:24:08:     self.run()
2025-10-12T20:24:08:     ~~~~~~~~^^
2025-10-12T20:24:08:   File "C:\USERS\SAHAN\APPDATA\LOCAL\PROGRAMS\PYTHON\PYTHON313\Lib\threading.py", line 992, in run
2025-10-12T20:24:08:     self._target(*self._args, **self._kwargs)
2025-10-12T20:24:08:     ~~~~~~~~~~~~^^^^^^^^^^^^^^^^^^^^^^^^^^^^^
2025-10-12T20:24:08:   File "C:\Users\Sahan\Dark\Promise\genApp\backend\server.py", line 653, in gen_worker
2025-10-12T20:24:08:     job['callback'](None, error=str(e))
2025-10-12T20:24:08:     ~~~~~~~~~~~~~~~^^^^^^^^^^^^^^^^^^^^
2025-10-12T20:24:08: TypeError: health_generate.<locals>.dummy_callback() got an unexpected keyword argument 'error'
2025-10-12T20:25:07: INFO:firestore_service:Firestore service initialized for project: image-genie-ff577
2025-10-12T20:25:07: INFO:in_memory_store:In-memory token store initialized
2025-10-12T20:26:08: INFO:werkzeug:WARNING: This is a development server. Do not use it in a production deployment. Use a production WSGI server instead.
2025-10-12T20:26:08:  * Running on all addresses (0.0.0.0)
2025-10-12T20:26:08:  * Running on http://127.0.0.1:5002
2025-10-12T20:26:08:  * Running on http://192.168.1.2:5002
2025-10-12T20:26:08: INFO:werkzeug:Press CTRL+C to quit
2025-10-12T20:26:48: INFO:werkzeug:127.0.0.1 - - [12/Oct/2025 20:26:48] "GET /api/health-generate HTTP/1.1" 200 -
2025-10-12T20:26:48: Exception in thread Thread-1 (gen_worker):
2025-10-12T20:26:48: Traceback (most recent call last):
2025-10-12T20:26:48:   File "C:\Users\Sahan\Dark\Promise\genApp\backend\server.py", line 645, in gen_worker
2025-10-12T20:26:48:     image = gen.play(prompt, style)
2025-10-12T20:26:48:   File "C:\Users\Sahan\Dark\Promise\genApp\backend\gen.py", line 116, in play
2025-10-12T20:26:48:     self.set_style(style)  # Set default style
2025-10-12T20:26:48:     ~~~~~~~~~~~~~~^^^^^^^
2025-10-12T20:26:48:   File "C:\Users\Sahan\Dark\Promise\genApp\backend\gen.py", line 105, in set_style
2025-10-12T20:26:48:     style_select.click()
2025-10-12T20:26:48:     ~~~~~~~~~~~~~~~~~~^^
2025-10-12T20:26:48:   File "C:\USERS\SAHAN\APPDATA\LOCAL\PROGRAMS\PYTHON\PYTHON313\Lib\site-packages\selenium\webdriver\remote\webelement.py", line 120, in click
2025-10-12T20:26:48:     self._execute(Command.CLICK_ELEMENT)
2025-10-12T20:26:48:     ~~~~~~~~~~~~~^^^^^^^^^^^^^^^^^^^^^^^
2025-10-12T20:26:48:   File "C:\USERS\SAHAN\APPDATA\LOCAL\PROGRAMS\PYTHON\PYTHON313\Lib\site-packages\selenium\webdriver\remote\webelement.py", line 573, in _execute
2025-10-12T20:26:48:     return self._parent.execute(command, params)
2025-10-12T20:26:48:            ~~~~~~~~~~~~~~~~~~~~^^^^^^^^^^^^^^^^^
2025-10-12T20:26:48:   File "C:\USERS\SAHAN\APPDATA\LOCAL\PROGRAMS\PYTHON\PYTHON313\Lib\site-packages\selenium\webdriver\remote\webdriver.py", line 454, in execute
2025-10-12T20:26:48:     self.error_handler.check_response(response)
2025-10-12T20:26:48:     ~~~~~~~~~~~~~~~~~~~~~~~~~~~~~~~~~^^^^^^^^^^
2025-10-12T20:26:48:   File "C:\USERS\SAHAN\APPDATA\LOCAL\PROGRAMS\PYTHON\PYTHON313\Lib\site-packages\selenium\webdriver\remote\errorhandler.py", line 232, in check_response
2025-10-12T20:26:48:     raise exception_class(message, screen, stacktrace)
2025-10-12T20:26:48: selenium.common.exceptions.WebDriverException: Message: unknown error: no element reference returned by script
2025-10-12T20:26:48:   (Session info: chrome=141.0.7390.66)
2025-10-12T20:26:48: Stacktrace:
2025-10-12T20:26:48: 	GetHandleVerifier [0x0x7ff76e619f25+80677]
2025-10-12T20:26:48: 	GetHandleVerifier [0x0x7ff76e619f80+80768]
2025-10-12T20:26:48: 	(No symbol) [0x0x7ff76e3c02bf]
2025-10-12T20:26:48: 	(No symbol) [0x0x7ff76e41b891]
2025-10-12T20:26:48: 	(No symbol) [0x0x7ff76e41a460]
2025-10-12T20:26:48: 	(No symbol) [0x0x7ff76e40b988]
2025-10-12T20:26:48: 	(No symbol) [0x0x7ff76e44150a]
2025-10-12T20:26:48: 	(No symbol) [0x0x7ff76e40b216]
2025-10-12T20:26:48: 	(No symbol) [0x0x7ff76e441720]
2025-10-12T20:26:48: 	(No symbol) [0x0x7ff76e4699c0]
2025-10-12T20:26:48: 	(No symbol) [0x0x7ff76e4412e3]
2025-10-12T20:26:48: 	(No symbol) [0x0x7ff76e409770]
2025-10-12T20:26:48: 	(No symbol) [0x0x7ff76e40a5a3]
2025-10-12T20:26:48: 	GetHandleVerifier [0x0x7ff76e8f817d+3087741]
2025-10-12T20:26:48: 	GetHandleVerifier [0x0x7ff76e8f223a+3063354]
2025-10-12T20:26:48: 	GetHandleVerifier [0x0x7ff76e9132c5+3198661]
2025-10-12T20:26:48: 	GetHandleVerifier [0x0x7ff76e63412e+187694]
2025-10-12T20:26:48: 	GetHandleVerifier [0x0x7ff76e63b20f+216591]
2025-10-12T20:26:48: 	GetHandleVerifier [0x0x7ff76e622ee4+117476]
2025-10-12T20:26:48: 	GetHandleVerifier [0x0x7ff76e62309f+117919]
2025-10-12T20:26:48: 	GetHandleVerifier [0x0x7ff76e6091a8+11688]
2025-10-12T20:26:48: 	BaseThreadInitThunk [0x0x7ffa4d61e8d7+23]
2025-10-12T20:26:48: 	RtlUserThreadStart [0x0x7ffa4e968d9c+44]
2025-10-12T20:26:48: 
2025-10-12T20:26:48: 
2025-10-12T20:26:48: During handling of the above exception, another exception occurred:
2025-10-12T20:26:48: 
2025-10-12T20:26:48: Traceback (most recent call last):
2025-10-12T20:26:48:   File "C:\USERS\SAHAN\APPDATA\LOCAL\PROGRAMS\PYTHON\PYTHON313\Lib\threading.py", line 1041, in _bootstrap_inner
2025-10-12T20:26:48:     self.run()
2025-10-12T20:26:48:     ~~~~~~~~^^
2025-10-12T20:26:48:   File "C:\USERS\SAHAN\APPDATA\LOCAL\PROGRAMS\PYTHON\PYTHON313\Lib\threading.py", line 992, in run
2025-10-12T20:26:48:     self._target(*self._args, **self._kwargs)
2025-10-12T20:26:48:     ~~~~~~~~~~~~^^^^^^^^^^^^^^^^^^^^^^^^^^^^^
2025-10-12T20:26:48:   File "C:\Users\Sahan\Dark\Promise\genApp\backend\server.py", line 653, in gen_worker
2025-10-12T20:26:48:     job['callback'](None, error=str(e))
2025-10-12T20:26:48:     ~~~~~~~~~~~~~~~^^^^^^^^^^^^^^^^^^^^
2025-10-12T20:26:48: TypeError: health_generate.<locals>.dummy_callback() got an unexpected keyword argument 'error'
2025-10-12T20:33:08: INFO:firestore_service:Firestore service initialized for project: image-genie-ff577
2025-10-12T20:33:08: INFO:in_memory_store:In-memory token store initialized
2025-10-12T20:33:08: Traceback (most recent call last):
2025-10-12T20:33:08:   File "C:\Users\Sahan\Dark\Promise\genApp\backend\gen.py", line 34, in __init__
2025-10-12T20:33:08:     self.driver = Driver(
2025-10-12T20:33:08:                   ~~~~~~^
2025-10-12T20:33:08:         uc=True,
2025-10-12T20:33:08:         ^^^^^^^^
2025-10-12T20:33:08:     ...<2 lines>...
2025-10-12T20:33:08:         downloads_path=self.downloaded_files  # Worker-specific downloads
2025-10-12T20:33:08:         ^^^^^^^^^^^^^^^^^^^^^^^^^^^^^^^^^^^^^^^^^^^^^^^^^^^^^^^^^^^^^^^^^
2025-10-12T20:33:08:     )
2025-10-12T20:33:08:     ^
2025-10-12T20:33:08: TypeError: Driver() got an unexpected keyword argument 'downloads_path'
2025-10-12T20:33:08: INFO:werkzeug:WARNING: This is a development server. Do not use it in a production deployment. Use a production WSGI server instead.
2025-10-12T20:33:08:  * Running on all addresses (0.0.0.0)
2025-10-12T20:33:08:  * Running on http://127.0.0.1:5002
2025-10-12T20:33:08:  * Running on http://192.168.1.2:5002
2025-10-12T20:33:08: INFO:werkzeug:Press CTRL+C to quit
2025-10-12T20:35:23: INFO:firestore_service:Firestore service initialized for project: image-genie-ff577
2025-10-12T20:35:23: INFO:in_memory_store:In-memory token store initialized
2025-10-12T20:35:52: Traceback (most recent call last):
2025-10-12T20:35:52:   File "C:\Users\Sahan\Dark\Promise\genApp\backend\gen.py", line 46, in __init__
2025-10-12T20:35:52:     self.driver.execute_script("window.localStorage.setItem('sensitiveContentVisibility', 'warn');")
2025-10-12T20:35:52:     ~~~~~~~~~~~~~~~~~~~~~~~~~~^^^^^^^^^^^^^^^^^^^^^^^^^^^^^^^^^^^^^^^^^^^^^^^^^^^^^^^^^^^^^^^^^^^^^^
2025-10-12T20:35:52:   File "C:\USERS\SAHAN\APPDATA\LOCAL\PROGRAMS\PYTHON\PYTHON313\Lib\site-packages\selenium\webdriver\remote\webdriver.py", line 551, in execute_script
2025-10-12T20:35:52:     return self.execute(command, {"script": script, "args": converted_args})["value"]
2025-10-12T20:35:52:            ~~~~~~~~~~~~^^^^^^^^^^^^^^^^^^^^^^^^^^^^^^^^^^^^^^^^^^^^^^^^^^^^^
2025-10-12T20:35:52:   File "C:\USERS\SAHAN\APPDATA\LOCAL\PROGRAMS\PYTHON\PYTHON313\Lib\site-packages\selenium\webdriver\remote\webdriver.py", line 454, in execute
2025-10-12T20:35:52:     self.error_handler.check_response(response)
2025-10-12T20:35:52:     ~~~~~~~~~~~~~~~~~~~~~~~~~~~~~~~~~^^^^^^^^^^
2025-10-12T20:35:52:   File "C:\USERS\SAHAN\APPDATA\LOCAL\PROGRAMS\PYTHON\PYTHON313\Lib\site-packages\selenium\webdriver\remote\errorhandler.py", line 232, in check_response
2025-10-12T20:35:52:     raise exception_class(message, screen, stacktrace)
2025-10-12T20:35:52: selenium.common.exceptions.NoSuchWindowException: Message: no such window: target window already closed
2025-10-12T20:35:52: from unknown error: web view not found
2025-10-12T20:35:52:   (Session info: chrome=141.0.7390.66)
2025-10-12T20:35:52: Stacktrace:
2025-10-12T20:35:52: 	GetHandleVerifier [0x0x7ff76e619f25+80677]
2025-10-12T20:35:52: 	GetHandleVerifier [0x0x7ff76e619f80+80768]
2025-10-12T20:35:52: 	(No symbol) [0x0x7ff76e3c02bf]
2025-10-12T20:35:52: 	(No symbol) [0x0x7ff76e398041]
2025-10-12T20:35:52: 	(No symbol) [0x0x7ff76e448b8e]
2025-10-12T20:35:52: 	(No symbol) [0x0x7ff76e4692d2]
2025-10-12T20:35:52: 	(No symbol) [0x0x7ff76e4412e3]
2025-10-12T20:35:52: 	(No symbol) [0x0x7ff76e409770]
2025-10-12T20:35:52: 	(No symbol) [0x0x7ff76e40a5a3]
2025-10-12T20:35:52: 	GetHandleVerifier [0x0x7ff76e8f817d+3087741]
2025-10-12T20:35:52: 	GetHandleVerifier [0x0x7ff76e8f223a+3063354]
2025-10-12T20:35:52: 	GetHandleVerifier [0x0x7ff76e9132c5+3198661]
2025-10-12T20:35:52: 	GetHandleVerifier [0x0x7ff76e63412e+187694]
2025-10-12T20:35:52: 	GetHandleVerifier [0x0x7ff76e63b20f+216591]
2025-10-12T20:35:52: 	GetHandleVerifier [0x0x7ff76e622ee4+117476]
2025-10-12T20:35:52: 	GetHandleVerifier [0x0x7ff76e62309f+117919]
2025-10-12T20:35:52: 	GetHandleVerifier [0x0x7ff76e6091a8+11688]
2025-10-12T20:35:52: 	BaseThreadInitThunk [0x0x7ffa4d61e8d7+23]
2025-10-12T20:35:52: 	RtlUserThreadStart [0x0x7ffa4e968d9c+44]
2025-10-12T20:35:52: 
2025-10-12T20:35:52: INFO:werkzeug:WARNING: This is a development server. Do not use it in a production deployment. Use a production WSGI server instead.
2025-10-12T20:35:52: 
2025-10-12T20:35:52:  * Running on all addresses (0.0.0.0)
2025-10-12T20:35:52:  * Running on http://127.0.0.1:5002
2025-10-12T20:35:52:  * Running on http://192.168.1.2:5002
2025-10-12T20:35:52: INFO:werkzeug:Press CTRL+C to quit
2025-10-12T20:38:59: INFO:firestore_service:Firestore service initialized for project: image-genie-ff577
2025-10-12T20:38:59: INFO:in_memory_store:In-memory token store initialized
2025-10-12T20:39:59: INFO:werkzeug:WARNING: This is a development server. Do not use it in a production deployment. Use a production WSGI server instead.
2025-10-12T20:39:59:  * Running on all addresses (0.0.0.0)
2025-10-12T20:39:59:  * Running on http://127.0.0.1:5002
2025-10-12T20:39:59:  * Running on http://192.168.1.2:5002
2025-10-12T20:39:59: INFO:werkzeug:Press CTRL+C to quit
2025-10-12T20:40:41: INFO:werkzeug:127.0.0.1 - - [12/Oct/2025 20:40:41] "GET /api/health-generate HTTP/1.1" 200 -
2025-10-12T20:42:38: INFO:firestore_service:Firestore service initialized for project: image-genie-ff577
2025-10-12T20:42:38: INFO:in_memory_store:In-memory token store initialized
2025-10-12T20:43:38: INFO:werkzeug:WARNING: This is a development server. Do not use it in a production deployment. Use a production WSGI server instead.
2025-10-12T20:43:38:  * Running on all addresses (0.0.0.0)
2025-10-12T20:43:38:  * Running on http://127.0.0.1:5002
2025-10-12T20:43:38:  * Running on http://192.168.1.2:5002
2025-10-12T20:43:38: INFO:werkzeug:Press CTRL+C to quit
2025-10-12T20:46:30: INFO:firestore_service:Firestore service initialized for project: image-genie-ff577
2025-10-12T20:46:30: INFO:in_memory_store:In-memory token store initialized
2025-10-12T20:47:24: INFO:werkzeug:WARNING: This is a development server. Do not use it in a production deployment. Use a production WSGI server instead.
2025-10-12T20:47:24:  * Running on all addresses (0.0.0.0)
2025-10-12T20:47:24:  * Running on http://127.0.0.1:5002
2025-10-12T20:47:24:  * Running on http://192.168.1.2:5002
2025-10-12T20:47:24: INFO:werkzeug:Press CTRL+C to quit
2025-10-12T20:56:35: INFO:werkzeug:127.0.0.1 - - [12/Oct/2025 20:56:35] "GET /api/health-generate HTTP/1.1" 200 -
2025-10-12T21:37:29: INFO:firestore_service:Firestore service initialized for project: image-genie-ff577
2025-10-12T21:37:29: INFO:in_memory_store:In-memory token store initialized
2025-10-12T21:38:44: INFO:werkzeug:WARNING: This is a development server. Do not use it in a production deployment. Use a production WSGI server instead.
2025-10-12T21:38:44:  * Running on all addresses (0.0.0.0)
2025-10-12T21:38:44:  * Running on http://127.0.0.1:5002
2025-10-12T21:38:44:  * Running on http://192.168.1.2:5002
2025-10-12T21:38:44: 
2025-10-12T21:57:57: INFO:firestore_service:Retrieved profile for user uz17AKYoaQNqUxZwisTZ32rmrz73
2025-10-12T21:57:57: INFO:firestore_service:User uz17AKYoaQNqUxZwisTZ32rmrz73 has 53 tokens
2025-10-12T21:57:59: INFO:firestore_service:Retrieved profile for user uz17AKYoaQNqUxZwisTZ32rmrz73
2025-10-12T21:58:00: INFO:firestore_service:Updated user profile for uz17AKYoaQNqUxZwisTZ32rmrz73
2025-10-12T21:58:00: INFO:firestore_service:Token consumed for user uz17AKYoaQNqUxZwisTZ32rmrz73. Remaining: 52
2025-10-12T21:58:00: INFO:werkzeug:192.168.1.3 - - [12/Oct/2025 21:58:00] "POST /api/generate HTTP/1.1" 200 -
2025-10-12T21:58:52: INFO:firestore_service:Retrieved profile for user uz17AKYoaQNqUxZwisTZ32rmrz73
2025-10-12T21:58:52: INFO:firestore_service:User uz17AKYoaQNqUxZwisTZ32rmrz73 has 52 tokens
2025-10-12T21:58:53: INFO:firestore_service:Retrieved profile for user uz17AKYoaQNqUxZwisTZ32rmrz73
2025-10-12T21:58:54: INFO:firestore_service:Updated user profile for uz17AKYoaQNqUxZwisTZ32rmrz73
2025-10-12T21:58:54: INFO:firestore_service:Token consumed for user uz17AKYoaQNqUxZwisTZ32rmrz73. Remaining: 51
2025-10-12T21:58:54: INFO:werkzeug:192.168.1.3 - - [12/Oct/2025 21:58:54] "POST /api/generate HTTP/1.1" 200 -
2025-10-12T22:07:05: INFO:firestore_service:Firestore service initialized for project: image-genie-ff577
2025-10-12T22:07:05: INFO:in_memory_store:In-memory token store initialized
2025-10-12T22:08:36: INFO:werkzeug:WARNING: This is a development server. Do not use it in a production deployment. Use a production WSGI server instead.
2025-10-12T22:08:36:  * Running on all addresses (0.0.0.0)
2025-10-12T22:08:36:  * Running on http://127.0.0.1:5002
2025-10-12T22:08:36:  * Running on http://192.168.1.2:5002
2025-10-12T22:08:36: INFO:werkzeug:Press CTRL+C to quit
2025-10-12T22:08:43: INFO:firestore_service:Retrieved profile for user uz17AKYoaQNqUxZwisTZ32rmrz73
2025-10-12T22:08:43: INFO:firestore_service:User uz17AKYoaQNqUxZwisTZ32rmrz73 has 49 tokens
2025-10-12T22:08:44: INFO:firestore_service:Retrieved profile for user uz17AKYoaQNqUxZwisTZ32rmrz73
2025-10-12T22:08:45: INFO:firestore_service:Updated user profile for uz17AKYoaQNqUxZwisTZ32rmrz73
2025-10-12T22:08:45: INFO:firestore_service:Token consumed for user uz17AKYoaQNqUxZwisTZ32rmrz73. Remaining: 48
2025-10-12T22:09:35: INFO:werkzeug:192.168.1.3 - - [12/Oct/2025 22:09:35] "POST /api/generate HTTP/1.1" 200 -
2025-10-12T22:09:37: INFO:firestore_service:Retrieved profile for user uz17AKYoaQNqUxZwisTZ32rmrz73
2025-10-12T22:09:37: INFO:werkzeug:192.168.1.3 - - [12/Oct/2025 22:09:37] "GET /api/user/tokens HTTP/1.1" 200 -
2025-10-12T22:11:25: INFO:firestore_service:Retrieved profile for user uz17AKYoaQNqUxZwisTZ32rmrz73
2025-10-12T22:11:25: INFO:werkzeug:192.168.1.3 - - [12/Oct/2025 22:11:25] "GET /api/user/tokens HTTP/1.1" 200 -
2025-10-12T22:13:06: INFO:werkzeug:192.168.1.3 - - [12/Oct/2025 22:13:06] "POST /api/generate HTTP/1.1" 401 -
2025-10-12T22:13:12: INFO:werkzeug:192.168.1.3 - - [12/Oct/2025 22:13:12] "
2025-10-12T22:13:12: POST /api/generate HTTP/1.1" 401 -
2025-10-12T22:14:19: INFO:werkzeug:192.168.1.3 - - [12/Oct/2025 22:14:19] "POST /api/generate HTTP/1.1
2025-10-12T22:14:19: " 401 -
2025-10-12T22:20:30: INFO:firestore_service:Firestore service initialized for project: image-genie-ff577
2025-10-12T22:20:30: INFO:in_memory_store:In-memory token store initialized
2025-10-12T22:21:26: INFO:werkzeug:WARNING: This is a development server. Do not use it in a production deployment. Use a production WSGI server instead.
2025-10-12T22:21:26: 
2025-10-12T22:21:26:  * Running on all addresses (0.0.0.0)
2025-10-12T22:21:26:  * Running on http://127.0.0.1:5002
2025-10-12T22:21:26:  * Running on http://192.168.1.2:5002
2025-10-12T22:21:26: INFO:werkzeug:Press CTRL+C to quit
2025-10-12T22:23:37: INFO:firestore_service:Retrieved profile for user uz17AKYoaQNqUxZwisTZ32rmrz73
2025-10-12T22:23:37: INFO:firestore_service:User uz17AKYoaQNqUxZwisTZ32rmrz73 has 45 tokens
2025-10-12T22:23:38: INFO:firestore_service:Retrieved profile for user uz17AKYoaQNqUxZwisTZ32rmrz73
2025-10-12T22:23:40: INFO:firestore_service:Updated user profile for uz17AKYoaQNqUxZwisTZ32rmrz73
2025-10-12T22:23:40: INFO:firestore_service:Token consumed for user uz17AKYoaQNqUxZwisTZ32rmrz73. Remaining: 44
2025-10-12T22:24:09: INFO:werkzeug:192.168.1.3 - - [12/Oct/2025 22:24:09] "POST /api/generate HTTP/1.1" 200 -
2025-10-12T22:24:13: INFO:firestore_service:Retrieved profile for user uz17AKYoaQNqUxZwisTZ32rmrz73
2025-10-12T22:24:13: INFO:werkzeug:192.168.1.3 - - [12/Oct/2025 22:24:13] "GET /api/user/tokens HTTP/1.1" 200 -
2025-10-12T22:24:46: INFO:firestore_service:Retrieved profile for user uz17AKYoaQNqUxZwisTZ32rmrz73
2025-10-12T22:24:46: INFO:werkzeug:192.168.1.3 - - [12/Oct/2025 22:24:46] "GET /api/user/tokens HTTP/1.1" 200 -
